<?xml version="1.0" encoding="utf-8"?>
<!-- This URDF was automatically created by SolidWorks to URDF Exporter! Originally created by Stephen Brawner (brawner@gmail.com) 
     Commit Version: 1.6.0-4-g7f85cfe  Build Version: 1.6.7995.38578
     For more information, please see http://wiki.ros.org/sw_urdf_exporter -->
<robot
  name="rover_description">
  <link
    name="base_link">
    <inertial>
      <origin
        xyz="3.21E-06 6.9337E-07 0.03604"
        rpy="0 0 0" />
      <mass
        value="1.5248" />
      <inertia
        ixx="0.0052172"
        ixy="-2.3731E-07"
        ixz="1.5083E-07"
        iyy="0.031715"
        iyz="3.2579E-08"
        izz="0.029684" />
    </inertial>
    <visual>
      <origin
        xyz="0 0 0"
        rpy="0 0 0" />
      <geometry>
        <mesh
          filename="package://rover_gz_description/meshes/base_link.STL" />
      </geometry>
      <material
        name="">
        <color
          rgba="0.75294 0.75294 0.75294 1" />
      </material>
    </visual>
    <collision>
      <origin
        xyz="0 0 0"
        rpy="0 0 0" />
      <geometry>
        <mesh
          filename="package://rover_gz_description/meshes/base_link.STL" />
      </geometry>
    </collision>
  </link>
  <link
    name="Wheel1_Link">
    <inertial>
      <origin
        xyz="-2.7756E-17 6.9389E-18 0.052583"
        rpy="0 0 0" />
      <mass
        value="1.8933" />
      <inertia
        ixx="0.011647"
        ixy="4.4141E-19"
        ixz="-3.5048E-19"
        iyy="0.011647"
        iyz="-1.1485E-18"
        izz="0.022319" />
    </inertial>
    <visual>
      <origin
        xyz="0 0 0"
        rpy="0 0 0" />
      <geometry>
        <mesh
          filename="package://rover_gz_description/meshes/Wheel1_Link.STL" />
      </geometry>
      <material
        name="">
        <color
          rgba="0.75294 0.75294 0.75294 1" />
      </material>
    </visual>
    <collision>
      <origin
        xyz="0 0 0"
        rpy="0 0 0" />
      <geometry>
        <mesh
          filename="package://rover_gz_description/meshes/Wheel1_Link.STL" />
      </geometry>
    </collision>
  </link>
  <joint
    name="Joint1"
    type="continuous">
    <origin
      xyz="-0.17 0 0.11186"
      rpy="1.5708 0 -1.5708" />
    <parent
      link="base_link" />
    <child
      link="Wheel1_Link" />
    <axis
      xyz="0 0 1" />
  </joint>
  <link
    name="Wheel2_Link">
    <inertial>
      <origin
        xyz="-6.9389E-18 0 -0.032896"
        rpy="0 0 0" />
      <mass
        value="1.8933" />
      <inertia
        ixx="0.011647"
        ixy="8.6736E-19"
        ixz="2.1965E-19"
        iyy="0.011647"
        iyz="-1.2042E-18"
        izz="0.022319" />
    </inertial>
    <visual>
      <origin
        xyz="0 0 0"
        rpy="0 0 0" />
      <geometry>
        <mesh
          filename="package://rover_gz_description/meshes/Wheel2_Link.STL" />
      </geometry>
      <material
        name="">
        <color
          rgba="0.75294 0.75294 0.75294 1" />
      </material>
    </visual>
    <collision>
      <origin
        xyz="0 0 0"
        rpy="0 0 0" />
      <geometry>
        <mesh
          filename="package://rover_gz_description/meshes/Wheel2_Link.STL" />
      </geometry>
    </collision>
  </link>
  <joint
    name="Joint2"
    type="continuous">
    <origin
      xyz="0.25548 0 0.11186"
      rpy="-1.5708 -0.39309 -1.5708" />
    <parent
      link="base_link" />
    <child
      link="Wheel2_Link" />
    <axis
      xyz="0 0 -1" />
  </joint>
  <link
    name="Camara_Link">
    <inertial>
      <origin
        xyz="-1.3986E-09 -0.00025169 0.0073239"
        rpy="0 0 0" />
      <mass
        value="0.21094" />
      <inertia
        ixx="4.3606E-05"
        ixy="-4.2289E-12"
        ixz="2.1372E-14"
        iyy="4.2661E-05"
        iyz="-6.5426E-15"
        izz="4.7389E-05" />
    </inertial>
    <visual>
      <origin
        xyz="0 0 0"
        rpy="0 0 0" />
      <geometry>
        <mesh
          filename="package://rover_gz_description/meshes/Camara_Link.STL" />
      </geometry>
      <material
        name="">
        <color
          rgba="0.75294 0.75294 0.75294 1" />
      </material>
    </visual>
    <collision>
      <origin
        xyz="0 0 0"
        rpy="0 0 0" />
      <geometry>
        <mesh
          filename="package://rover_gz_description/meshes/Camara_Link.STL" />
      </geometry>
    </collision>
  </link>
  <joint
    name="Joint3"
    type="continuous">
    <origin
      xyz="0 0 0.05"
      rpy="0 0 0" />
    <parent
      link="base_link" />
    <child
      link="Camara_Link" />
    <axis
      xyz="0 0 1" />
  </joint>

  <gazebo>
    <plugin name="two_wheeled_robot_diff_drive" filename="libgazebo_ros_diff_drive.so">
      <update_rate>100</update_rate>

      <left_joint>Joint1</left_joint>
      <right_joint>Joint2</right_joint>

      <wheel_separation>0.14022037</wheel_separation>
      <wheel_diameter>0.033</wheel_diameter>

      <max_wheel_torque>20.0</max_wheel_torque>
      <max_wheel_acceleration>20.0</max_wheel_acceleration>

      <command_topic>cmd_vel</command_topic>

      <publish_odom>true</publish_odom>
      <publish_odom_tf>true</publish_odom_tf>
      <publish_wheel_tf>true</publish_wheel_tf>
      
      <odometry_topic>odom</odometry_topic>
      <odometry_frame>odom_link</odometry_frame>
      <robot_base_frame>base_link</robot_base_frame>

      <odometry_source>1</odometry_source>
      <ros>
        <remapping>odom:=wheel/odometry</remapping>
      </ros>
    </plugin>
  </gazebo>

</robot>